<?xml version="1.0"?>
<!-- This URDF was automatically created by SolidWorks to URDF Exporter! Originally created by Stephen Brawner (brawner@gmail.com) 
     Commit Version: 1.6.0-4-g7f85cfe  Build Version: 1.6.7995.38578
     For more information, please see http://wiki.ros.org/sw_urdf_exporter -->
<robot
  name="robot_arm" xmlns:xacro="http://ros.org/wiki/xacro">
  <link
    name="dummy_link">
  </link>
  <joint name="world_to_base" type="fixed">
    <parent link="dummy_link" />
    <child link="base_link" />
  </joint>
  <link
    name="base_link">
    <inertial>
      <origin
        xyz="-1.57352883492569E-17 1.23806099488061E-05 0.122640352107562"
        rpy="0 0 0" />
      <mass
        value="383.081449459895" />
      <inertia
        ixx="58.1375887219717"
        ixy="-1.44642598326101E-17"
        ixz="-7.58220860830791E-16"
        iyy="58.1958047662382"
        iyz="-0.00371056125895548"
        izz="65.7719404506967" />
    </inertial>
    <visual>
      <origin
        xyz="0 0 0"
        rpy="0 0 0" />
      <geometry>
        <mesh
          filename="package://robot_arm/meshes/base_link.STL" />
      </geometry>
      <material
        name="">
        <color
          rgba="0.529411764705882 0.549019607843137 0.549019607843137 1" />
      </material>
    </visual>
    <collision>
      <origin
        xyz="0 0 0"
        rpy="0 0 0" />
      <geometry>
        <mesh
          filename="package://robot_arm/meshes/base_link.STL" />
      </geometry>
    </collision>
  </link>
  <link
    name="ShoulderRoll">
    <inertial>
      <origin
        xyz="-5.81435209049046E-09 -0.000268793895158659 0.0993228983847673"
        rpy="0 0 0" />
      <mass
        value="9.85109974289092" />
      <inertia
        ixx="0.0613405938790785"
        ixy="8.25312500811482E-10"
        ixz="-2.809904082228E-09"
        iyy="0.137308343564358"
        iyz="0.000174174641087882"
        izz="0.102034002600403" />
    </inertial>
    <visual>
      <origin
        xyz="0 0 0"
        rpy="0 0 0" />
      <geometry>
        <mesh
          filename="package://robot_arm/meshes/ShoulderRoll.STL" />
      </geometry>
      <material
        name="">
        <color
          rgba="0.898039215686275 0.917647058823529 0.929411764705882 1" />
      </material>
    </visual>
    <collision>
      <origin
        xyz="0 0 0"
        rpy="0 0 0" />
      <geometry>
        <mesh
          filename="package://robot_arm/meshes/ShoulderRoll.STL" />
      </geometry>
    </collision>
  </link>
  <joint
    name="ShoulderRollJoint"
    type="continuous">
    <origin
      xyz="0 0.05 0.905"
      rpy="-1.5708 0 0" />
    <parent
      link="base_link" />
    <child
      link="ShoulderRoll" />
    <axis
      xyz="0 0 -1" />
    <limit lower="-1.57" upper="1.57" effort="50" velocity="2.0" />
    <!-- <dynamics damping="0.5" friction="0.1"/> -->
  </joint>
  <link
    name="ShoulderPitch">
    <inertial>
      <origin
        xyz="0.00473656064901562 4.19347445657081E-10 -3.48717429845378E-08"
        rpy="0 0 0" />
      <mass
        value="1.06855896217137" />
      <inertia
        ixx="0.00195027405173375"
        ixy="-2.0516299161287E-11"
        ixz="8.25064628040536E-09"
        iyy="0.00172938597831085"
        iyz="7.77987030782786E-10"
        izz="0.00181389222703697" />
    </inertial>
    <visual>
      <origin
        xyz="0 0 0"
        rpy="0 0 0" />
      <geometry>
        <mesh
          filename="package://robot_arm/meshes/ShoulderPitch.STL" />
      </geometry>
      <material
        name="">
        <color
          rgba="1 1 1 1" />
      </material>
    </visual>
    <collision>
      <origin
        xyz="0 0 0"
        rpy="0 0 0" />
      <geometry>
        <mesh
          filename="package://robot_arm/meshes/ShoulderPitch.STL" />
      </geometry>
    </collision>
  </link>
  <joint
    name="ShoulderPitchJoint"
    type="continuous">
    <origin
      xyz="0 -0.0127 0.1651"
      rpy="1.5708 0 1.5708" />
    <parent
      link="ShoulderRoll" />
    <child
      link="ShoulderPitch" />
    <axis
      xyz="0 0 -1" />
    <limit lower="-1.57" upper="1.57" effort="50" velocity="2.0" />
    <!-- <dynamics damping="0.5" friction="0.1"/> -->
  </joint>
  <link
    name="ArmRoll">
    <inertial>
      <origin
        xyz="6.3099446778736E-09 -2.08610865706113E-07 -0.0923046120686624"
        rpy="0 0 0" />
      <mass
        value="1.45084951290082" />
      <inertia
        ixx="0.00637777449209472"
        ixy="-1.03845542105536E-10"
        ixz="8.56636979302991E-10"
        iyy="0.00638088171946136"
        iyz="-3.5818422563623E-08"
        izz="0.00165573890312906" />
    </inertial>
    <visual>
      <origin
        xyz="0 0 0"
        rpy="0 0 0" />
      <geometry>
        <mesh
          filename="package://robot_arm/meshes/ArmRoll.STL" />
      </geometry>
      <material
        name="">
        <color
          rgba="1 1 1 1" />
      </material>
    </visual>
    <collision>
      <origin
        xyz="0 0 0"
        rpy="0 0 0" />
      <geometry>
        <mesh
          filename="package://robot_arm/meshes/ArmRoll.STL" />
      </geometry>
    </collision>
  </link>
  <joint
    name="ArmRollJoint"
    type="continuous">
    <origin
      xyz="0.049148 0 0"
      rpy="-1.5708 0 1.5708" />
    <parent
      link="ShoulderPitch" />
    <child
      link="ArmRoll" />
    <axis
      xyz="0 0 -1" />
    <limit lower="-1.57" upper="1.57" effort="50" velocity="2.0" />
    <!-- <dynamics damping="0.5" friction="0.1"/> -->
  </joint>
  <link
    name="Elbow">
    <inertial>
      <origin
        xyz="9.71542672423276E-08 -0.133354220965053 -1.1938262017568E-07"
        rpy="0 0 0" />
      <mass
        value="2.42596161120103" />
      <inertia
        ixx="0.00954634993260107"
        ixy="-8.48967464784282E-09"
        ixz="3.93045018269851E-09"
        iyy="0.00376347633999173"
        iyz="2.35122944861129E-08"
        izz="0.0083767423411937" />
    </inertial>
    <visual>
      <origin
        xyz="0 0 0"
        rpy="0 0 0" />
      <geometry>
        <mesh
          filename="package://robot_arm/meshes/Elbow.STL" />
      </geometry>
      <material
        name="">
        <color
          rgba="0.898039215686275 0.917647058823529 0.929411764705882 1" />
      </material>
    </visual>
    <collision>
      <origin
        xyz="0 0 0"
        rpy="0 0 0" />
      <geometry>
        <mesh
          filename="package://robot_arm/meshes/Elbow.STL" />
      </geometry>
    </collision>
  </link>
  <joint
    name="ElbowJoint"
    type="continuous">
    <origin
      xyz="0 0 -0.20588"
      rpy="1.5708 0 0" />
    <parent
      link="ArmRoll" />
    <child
      link="Elbow" />
    <axis
      xyz="0 0 -1" />
    <limit lower="-1.57" upper="1.57" effort="50" velocity="2.0" />
    <!-- <dynamics damping="0.5" friction="0.1"/> -->
  </joint>
  <link
    name="WristRoll">
    <inertial>
      <origin
        xyz="-5.70478676520381E-08 4.47641975016313E-08 0.0578513783180692"
        rpy="0 0 0" />
      <mass
        value="0.121855342582307" />
      <inertia
        ixx="0.000193294080215172"
        ixy="-8.73705063159057E-11"
        ixz="-1.00586970528501E-10"
        iyy="0.000127145484684631"
        iyz="9.55201535008496E-11"
        izz="8.5237004024183E-05" />
    </inertial>
    <visual>
      <origin
        xyz="0 0 0"
        rpy="0 0 0" />
      <geometry>
        <mesh
          filename="package://robot_arm/meshes/WristRoll.STL" />
      </geometry>
      <material
        name="">
        <color
          rgba="0.898039215686275 0.917647058823529 0.929411764705882 1" />
      </material>
    </visual>
    <collision>
      <origin
        xyz="0 0 0"
        rpy="0 0 0" />
      <geometry>
        <mesh
          filename="package://robot_arm/meshes/WristRoll.STL" />
      </geometry>
    </collision>
  </link>
  <joint
    name="WristRollJoint"
    type="continuous">
    <origin
      xyz="0 -0.33946 0"
      rpy="1.5708 0 0" />
    <parent
      link="Elbow" />
    <child
      link="WristRoll" />
    <axis
      xyz="0 0 1" />
    <limit lower="-1.57" upper="1.57" effort="50" velocity="2.0" />
    <!-- <dynamics damping="0.5" friction="0.1"/> -->
  </joint>
  <link
    name="WristPitch">
    <inertial>
      <origin
        xyz="0 -3.1172159298265E-10 3.84086784509088E-07"
        rpy="0 0 0" />
      <mass
        value="0.0946633788995506" />
      <inertia
        ixx="6.03757654449565E-05"
        ixy="2.56396644943696E-10"
        ixz="-2.31346819626229E-20"
        iyy="5.99849621521673E-05"
        iyz="3.08326765697005E-12"
        izz="7.59038124773005E-06" />
    </inertial>
    <visual>
      <origin
        xyz="0 0 0"
        rpy="0 0 0" />
      <geometry>
        <mesh
          filename="package://robot_arm/meshes/WristPitch.STL" />
      </geometry>
      <material
        name="">
        <color
          rgba="0.898039215686275 0.917647058823529 0.929411764705882 1" />
      </material>
    </visual>
    <collision>
      <origin
        xyz="0 0 0"
        rpy="0 0 0" />
      <geometry>
        <mesh
          filename="package://robot_arm/meshes/WristPitch.STL" />
      </geometry>
    </collision>
  </link>
  <joint
    name="WristPitchJoint"
    type="continuous">
    <origin
      xyz="0 0 0.088"
      rpy="-1.5708 0 3.1416" />
    <parent
      link="WristRoll" />
    <child
      link="WristPitch" />
    <axis
      xyz="0 0 -1" />
    <limit lower="-1.57" upper="1.57" effort="50" velocity="2.0" />
    <!-- <dynamics damping="0.5" friction="0.1"/> -->
  </joint>
  <link
    name="WristYaw">
    <inertial>
      <origin
        xyz="0.0503395415355519 6.01187888026514E-10 1.52382306772836E-09"
        rpy="0 0 0" />
      <mass
        value="0.330938909305297" />
      <inertia
        ixx="0.000180355244386451"
        ixy="1.90966456968596E-11"
        ixz="2.05060473907997E-11"
        iyy="0.000213755341670707"
        iyz="2.08711803729314E-11"
        izz="0.000125944224991248" />
    </inertial>
    <visual>
      <origin
        xyz="0 0 0"
        rpy="0 0 0" />
      <geometry>
        <mesh
          filename="package://robot_arm/meshes/WristYaw.STL" />
      </geometry>
      <material
        name="">
        <color
          rgba="0.898039215686275 0.917647058823529 0.929411764705882 1" />
      </material>
    </visual>
    <collision>
      <origin
        xyz="0 0 0"
        rpy="0 0 0" />
      <geometry>
        <mesh
          filename="package://robot_arm/meshes/WristYaw.STL" />
      </geometry>
    </collision>
  </link>
  <joint
    name="WristYawJoint"
    type="continuous">
    <origin
      xyz="0 0 0"
      rpy="1.5708 0 -1.5708" />
    <parent
      link="WristPitch" />
    <child
      link="WristYaw" />
    <axis
      xyz="0 0 -1" />
    <limit lower="-1.57" upper="1.57" effort="50" velocity="2.0" />
    <!-- <dynamics damping="0.5" friction="0.1"/> -->
  </joint>

  <ros2_control name="GazeboSystem" type="system">
    <hardware>
        <plugin>gazebo_ros2_control/GazeboSystem</plugin>
    </hardware>

    <!-- Velocity Controllers -->
    <joint name="ShoulderRollJoint">
        <command_interface name="velocity">
          <param name="min">-1000.0</param>
          <param name="max">1000.0</param>
        </command_interface>
        <state_interface name="position"/>
        <state_interface name="velocity"/>
    </joint>
    <joint name="ShoulderPitchJoint">
        <command_interface name="velocity">
          <param name="min">-1000.0</param>
          <param name="max">1000.0</param>
        </command_interface>
        <state_interface name="position"/>
        <state_interface name="velocity"/>
    </joint>
    <joint name="ArmRollJoint">
        <command_interface name="velocity">
          <param name="min">-1000.0</param>
          <param name="max">1000.0</param>
        </command_interface>
        <state_interface name="position"/>
        <state_interface name="velocity"/>
    </joint>
    <joint name="ElbowJoint">
        <command_interface name="velocity">
          <param name="min">-1000.0</param>
          <param name="max">1000.0</param>
        </command_interface>
        <state_interface name="position"/>
        <state_interface name="velocity"/>
    </joint>
    <joint name="WristRollJoint">
        <command_interface name="velocity">
          <param name="min">-1000.0</param>
          <param name="max">1000.0</param>
        </command_interface>
        <state_interface name="position"/>
        <state_interface name="velocity"/>
    </joint>
    <joint name="WristPitchJoint">
        <command_interface name="velocity">
          <param name="min">-1000.0</param>
          <param name="max">1000.0</param>
        </command_interface>
        <state_interface name="position"/>
        <state_interface name="velocity"/>
    </joint>
    <joint name="WristYawJoint">
        <command_interface name="velocity">
          <param name="min">-1000.0</param>
          <param name="max">1000.0</param>
        </command_interface>
        <state_interface name="position"/>
        <state_interface name="velocity"/>
    </joint>
  </ros2_control>
  
  <gazebo>
    <plugin filename="libgazebo_ros2_control.so" name="gazebo_ros2_control">
      <parameters>$(find robot_arm)/config/control.yaml</parameters>
    </plugin>
  </gazebo>

  <gazebo reference="ShoulderRoll">
   <turnGravityOff>true</turnGravityOff>
  </gazebo>
  <gazebo reference="ShoulderPitch">
   <turnGravityOff>true</turnGravityOff>
  </gazebo>
  <gazebo reference="ArmRoll">
   <turnGravityOff>true</turnGravityOff>
  </gazebo>
  <gazebo reference="Elbow">
   <turnGravityOff>true</turnGravityOff>
  </gazebo>
  <gazebo reference="WristRoll">
   <turnGravityOff>true</turnGravityOff>
  </gazebo>
  <gazebo reference="WristPitch">
   <turnGravityOff>true</turnGravityOff>
  </gazebo>
  <gazebo reference="WristYaw">
   <turnGravityOff>true</turnGravityOff>
  </gazebo>
</robot>